<?xml version="1.0"?>
<robot name="three_dof_arm">
  <link name="base_link"/>

  <joint name="joint1" type="revolute">
    <parent link="base_link"/>
    <child link="link1"/>
    <origin xyz="0 0 0.1" rpy="0 0 0"/>
    <axis xyz="0 0 1"/>
    <limit lower="-3.14" upper="3.14" effort="1" velocity="1"/>
  </joint>
  <link name="link1">
    <visual>
      <geometry>
        <cylinder length="0.5" radius="0.05"/>
      </geometry>
      <origin xyz="0 0 0.25" rpy="0 0 0"/>
    </visual>
  </link>

  <joint name="joint2" type="revolute">
    <parent link="link1"/>
    <child link="link2"/>
    <origin xyz="0 0 0.5" rpy="0 0 0"/>
    <axis xyz="0 1 0"/>
    <limit lower="-3.14" upper="3.14" effort="1" velocity="1"/>
  </joint>
  <link name="link2">
    <visual>
      <geometry>
        <cylinder length="0.4" radius="0.04"/>
      </geometry>
      <origin xyz="0 0 0.2" rpy="0 0 0"/>
    </visual>
  </link>

  <joint name="joint3" type="revolute">
    <parent link="link2"/>
    <child link="link3"/>
    <origin xyz="0 0 0.4" rpy="0 0 0"/>
    <axis xyz="0 1 0"/>
    <limit lower="-3.14" upper="3.14" effort="1" velocity="1"/>
  </joint>
  <link name="link3">
    <visual>
      <geometry>
        <cylinder length="0.3" radius="0.03"/>
      </geometry>
      <origin xyz="0 0 0.15" rpy="0 0 0"/>
    </visual>
  </link>

  <link name="ee_link"/>
  <joint name="ee_fixed" type="fixed">
    <parent link="link3"/>
    <child link="ee_link"/>
    <origin xyz="0 0 0.3" rpy="0 0 0"/>
  </joint>
</robot>
