<?xml version="1.0" ?>
<sdf version="1.6">
  <model name="three_dof_arm">
    <static>false</static>
    <link name="base_link">
      <visual>
        <geometry>
          <box>
            <size>0.2 0.2 0.05</size>
          </box>
        </geometry>
      </visual>
    </link>
    <link name="link1">
      <pose>0 0 0.05 0 0 0</pose>
      <visual>
        <geometry>
          <cylinder>
            <radius>0.03</radius>
            <length>0.5</length>
          </cylinder>
        </geometry>
      </visual>
    </link>
    <joint name="joint1" type="revolute">
      <parent>base_link</parent>
      <child>link1</child>
      <pose>0 0 0.05 0 0 0</pose>
      <axis>
        <xyz>0 0 1</xyz>
        <limit>
          <lower>-3.14</lower>
          <upper>3.14</upper>
        </limit>
      </axis>
    </joint>
    <link name="link2">
      <pose>0 0 0.5 0 0 0</pose>
      <visual>
        <geometry>
          <cylinder>
            <radius>0.03</radius>
            <length>0.4</length>
          </cylinder>
        </geometry>
      </visual>
    </link>
    <joint name="joint2" type="revolute">
      <parent>link1</parent>
      <child>link2</child>
      <pose>0 0 0.5 0 0 0</pose>
      <axis>
        <xyz>0 1 0</xyz>
        <limit>
          <lower>-3.14</lower>
          <upper>3.14</upper>
        </limit>
      </axis>
    </joint>
    <link name="link3">
      <pose>0 0 0.9 0 0 0</pose>
      <visual>
        <geometry>
          <cylinder>
            <radius>0.03</radius>
            <length>0.3</length>
          </cylinder>
        </geometry>
      </visual>
    </link>
    <joint name="joint3" type="revolute">
      <parent>link2</parent>
      <child>link3</child>
      <pose>0 0 0.9 0 0 0</pose>
      <axis>
        <xyz>0 1 0</xyz>
        <limit>
          <lower>-3.14</lower>
          <upper>3.14</upper>
        </limit>
      </axis>
    </joint>
  </model>
</sdf>
